
<?xml version="1.0"?>
<robot name="my_robot" xmlns:xacro="http://www.ros.org/wiki/xacro">

  <!-- Base Link (Main Body) -->
  <link name="base_link">
    <visual>
      <geometry>
        <box size="0.6 0.6 0.55"/>  <!-- 60cm x 60cm x 55cm -->
      </geometry>
      <material name="blue">
        <color rgba="0.0 0.5 1.0 1.0"/>  <!-- Blue Color -->
      </material>
    </visual>
    <collision>
      <geometry>
        <box size="0.6 0.6 0.55"/>
      </geometry>
    </collision>
  </link>

  <!-- Dummy Link to Fix KDL Inertia Issue -->
  <link name="dummy_link"/>
  <joint name="base_joint" type="fixed">
    <parent link="dummy_link"/>
    <child link="base_link"/>
    <origin xyz="0 0 0"/>
  </joint>



  <!-- Wheels: Changing joints to continuous for rotation -->
  <!-- Front Left Wheel -->
  <joint name="wheel_front_left_joint" type="continuous">
    <parent link="base_link"/>
    <child link="wheel_front_left"/>
    <origin xyz="0.3 0.3 -0.275" rpy="1.5708 0 0"/>
    <axis xyz="0 1 0"/>
  </joint>
  <link name="wheel_front_left">
    <visual>
      <geometry>
        <cylinder radius="0.1" length="0.05"/>
      </geometry>
      <material name="black">
        <color rgba="0 0 0 1"/>
      </material>
    </visual>
  </link>

  <!-- Front Right Wheel -->
  <joint name="wheel_front_right_joint" type="continuous">
    <parent link="base_link"/>
    <child link="wheel_front_right"/>
    <origin xyz="0.3 -0.3 -0.275" rpy="1.5708 0 0"/>
    <axis xyz="0 1 0"/>
  </joint>
  <link name="wheel_front_right">
    <visual>
      <geometry>
        <cylinder radius="0.1" length="0.05"/>
      </geometry>
      <material name="black">
        <color rgba="0 0 0 1"/>
      </material>
    </visual>
  </link>

  <!-- Rear Left Wheel -->
  <joint name="wheel_rear_left_joint" type="continuous">
    <parent link="base_link"/>
    <child link="wheel_rear_left"/>
    <origin xyz="-0.3 0.3 -0.275" rpy="1.5708 0 0"/>
    <axis xyz="0 1 0"/>
  </joint>
  <link name="wheel_rear_left">
    <visual>
      <geometry>
        <cylinder radius="0.1" length="0.05"/>
      </geometry>
      <material name="black">
        <color rgba="0 0 0 1"/>
      </material>
    </visual>
  </link>

  <!-- Rear Right Wheel -->
  <joint name="wheel_rear_right_joint" type="continuous">
    <parent link="base_link"/>
    <child link="wheel_rear_right"/>
    <origin xyz="-0.3 -0.3 -0.275" rpy="1.5708 0 0"/>
    <axis xyz="0 1 0"/>
  </joint>
  <link name="wheel_rear_right">
    <visual>
      <geometry>
        <cylinder radius="0.1" length="0.05"/>
      </geometry>
      <material name="black">
        <color rgba="0 0 0 1"/>
      </material>
    </visual>
  </link>

<!-- Adding Arms to the Front of the Robot -->
  <link name="arm_left">
    <visual>
      <geometry>
        <box size="0.2 0.05 0.05"/>  <!-- Arm extending forward -->
      </geometry>
      <material name="gray">
        <color rgba="0.5 0.5 0.5 1.0"/>
      </material>
    </visual>
  </link>
  <joint name="arm_left_joint" type="fixed">
    <parent link="base_link"/>
    <child link="arm_left"/>
    <origin xyz="0.4 0.3 0" rpy="0 0 0"/>
  </joint>

  <link name="arm_right">
    <visual>
      <geometry>
        <box size="0.2 0.05 0.05"/>  <!-- Arm extending forward -->
      </geometry>
      <material name="gray">
        <color rgba="0.5 0.5 0.5 1.0"/>
      </material>
    </visual>
  </link>
  <joint name="arm_right_joint" type="fixed">
    <parent link="base_link"/>
    <child link="arm_right"/>
    <origin xyz="0.4 -0.3 0" rpy="0 0 0"/>
  </joint>

  <!-- Hanging Plane Sheets -->
  <link name="sheet_left">
    <visual>
      <geometry>
        <box size="0.15 0.01 0.15"/>  <!-- Hanging sheet -->
      </geometry>
      <material name="black">
        <color rgba="0 0 0 1.0"/>
      </material>
    </visual>
  </link>
  <joint name="sheet_left_joint" type="fixed">
    <parent link="arm_left"/>
    <child link="sheet_left"/>
    <origin xyz="0.1 0 -0.075" rpy="0 0 0"/>
  </joint>

  <link name="sheet_right">
    <visual>
      <geometry>
        <box size="0.15 0.01 0.15"/>  <!-- Hanging sheet -->
      </geometry>
      <material name="black">
        <color rgba="0 0 0 1.0"/>
      </material>
    </visual>
  </link>
  <joint name="sheet_right_joint" type="fixed">
    <parent link="arm_right"/>
    <child link="sheet_right"/>
    <origin xyz="0.1 0 -0.075" rpy="0 0 0"/>
  </joint>

  <!-- ===================================================== -->
  <!--       CAMERA MOUNT and RealSense Sensor             -->
  <!-- ===================================================== -->

  <!-- Camera Mount: A simple mount on top of the chassis -->
  <link name="camera_mount">
    <visual>
      <geometry>
        <box size="0.1 0.1 0.05"/>  <!-- Simple box representation -->
      </geometry>
      <material name="gray">
        <color rgba="0.5 0.5 0.5 1.0"/>
      </material>
    </visual>
  </link>
  <joint name="camera_mount_joint" type="fixed">
    <parent link="base_link"/>
    <child link="camera_mount"/>
    <!-- Position the mount on top of the base; adjust as necessary -->
    <origin xyz="0 0 0.35" rpy="0 0 0"/>
  </joint>

  <!-- RealSense Link: Use a primitive shape (box) for visualization -->
  <link name="camera_link">
    <visual>
      <geometry>
        <box size="0.12 0.04 0.08"/>  <!-- Approximate dimensions of a D435i -->
      </geometry>
      <material name="black">
        <color rgba="0 0 0 1.0"/>
      </material>
    </visual>
  </link>
  <joint name="realsense_joint" type="fixed">
    <parent link="base_link"/>
    <child link="camera_link"/>
    <!-- Position the sensor on the mount. Adjust xyz as needed for correct placement. -->
    <origin xyz="0 0 0" rpy="0 0 0"/>
  </joint>

</robot>
